
<mujoco model="ant">
  <compiler angle="degree" coordinate="local" inertiafromgeom="true"/>
  <option integrator="RK4" timestep="0.01"/>
  <visual>
  <global offwidth="3840" offheight="2160"/>
  <map shadowscale=".05" />
  <quality shadowsize ="10000" />
  </visual>
  <custom>
    <numeric data="0.0 0.0 0.8711102550927979 1.0 0.0 0.0 0.0 0.0 1.0 0.0 -1.0 0.0 -1.0 0.0 1.0" name="init_qpos"/>
  </custom>
  <default>
    <joint armature="1" damping="1" limited="true"/>
    <geom conaffinity="0" condim="3" density="5.0" friction="1 0.5 0.5" margin="0.01" rgba="0.8 0.6 0.4 1"/>
  </default>
  <asset>
    <texture builtin="gradient" height="100" rgb1="1 1 1" rgb2="0.9 0.9 0.9" type="skybox" width="100"/>
    <texture builtin="flat" height="1278" mark="cross" markrgb="1 1 1" name="texgeom" random="0.01" rgb1="0.8 0.6 0.4" rgb2="0.8 0.6 0.4" type="cube" width="127"/>
    <texture name="tex_desert" builtin="flat" type="2d" width="128" height="128" rgb1="0.95 0.85 0.65" rgb2="0.9 0.8 0.6" mark="none" />
    <material name="mat_desert" texture="tex_desert" rgba="1 1 1 1" specular="0.01" shininess="0.1" reflectance="0.2" />
    <hfield name="floor_desert" file="desert.png" size="32 32 1.5 0.1"/>
  </asset>

  <worldbody>
    <light cutoff="100" diffuse="1 1 1" dir="-0 0 -1" directional="true" exponent="10" pos="0 0 5" specular=".1 .1 .1"  castshadow="false" />
    <light cutoff="200" diffuse=".3 .3 .3" dir="-1 -1 0" directional="true" exponent=".1" pos="3 3 0" specular=".1 .1 .1"  castshadow="true" />
    <geom name='floor1' material="mat_desert" pos='17 0 -1.5' type='hfield' conaffinity='1' rgba="1 1 1 1" condim='3' hfield="floor_desert" friction="0.4 0.005 0.0001" />
    <geom name='floor2' material="mat_desert" pos='81 0 -1.5' type='hfield' conaffinity='1' rgba="1 1 1 1" condim='3' hfield="floor_desert" friction="0.4 0.005 0.0001" />

    <body name="torso" pos="0 0 0.7298275602568677">
      <camera name="track" mode="trackcom" pos="0 -3 0.3" xyaxes="1 0 0 0 0 1"/>
      <geom name="torso_geom" pos="0 0 0" size="0.2599999997764826" type="sphere"/>
      <joint armature="0" damping="0" limited="false" margin="0.01" name="root" pos="0 0 0" type="free"/>
      <body name="front_left_leg" pos="0 0 0">
        <geom fromto="0.0 0.0 0.0 0.7 0.7 0.0" name="aux_1_geom" size="0.08999999977648258" type="capsule"/>
        <body name="aux_1" pos="0.7 0.7 0">
          <joint axis="0 0 1" name="hip_1" pos="0.0 0.0 0.0" range="-40 40" type="hinge"/>
          <geom fromto="0.0 0.0 0.0 0.7 0.5778027892112731 0.0" name="left_leg_geom" size="0.08999999977648258" type="capsule" />
          <body pos="0.7 0.5778027892112731 0" >
            <joint axis="-1 1 0" name="ankle_1" pos="0.0 0.0 0.0" range="30 100" type="hinge"/>
            <geom fromto="0.0 0.0 0.0 0.4099999997764826 0.4099999997764826 0.0" name="left_ankle_geom" size="0.12935991019010545" type="capsule"/>
          </body>
        </body>
      </body>
      <body name="front_right_leg" pos="0 0 0">
        <geom fromto="0.0 0.0 0.0 -0.7 0.7 0.0" name="aux_2_geom" size="0.08999999977648258" type="capsule"/>
        <body name="aux_2" pos="-0.7 0.7 0">
          <joint axis="0 0 1" name="hip_2" pos="0.0 0.0 0.0" range="-40 40" type="hinge"/>
          <geom fromto="0.0 0.0 0.0 -0.7 0.5778027892112731 0.0" name="right_leg_geom" size="0.08999999977648258" type="capsule"/>
          <body pos="-0.7 0.5778027892112731 0" >
            <joint axis="1 1 0" name="ankle_2" pos="0.0 0.0 0.0" range="-100 -30" type="hinge"/>
            <geom fromto="0.0 0.0 0.0 -0.4099999997764826 0.4099999997764826 0.0" name="right_ankle_geom" size="0.12935991019010545" type="capsule"/>
          </body>
        </body>
      </body>
      <body name="left_back_leg" pos="0 0 0">
        <geom fromto="0.0 0.0 0.0 -0.7 -0.7 0.0" name="aux_3_geom" size="0.08999999977648258" type="capsule"/>
        <body name="aux_3" pos="-0.7 -0.7 0">
          <joint axis="0 0 1" name="hip_3" pos="0.0 0.0 0.0" range="-40 40" type="hinge"/>
          <geom fromto="0.0 0.0 0.0 -0.7 -0.5778027892112731 0.0" name="back_leg_geom" size="0.08999999977648258" type="capsule"/>
          <body pos="-0.7 -0.5778027892112731 0" >
            <joint axis="-1 1 0" name="ankle_3" pos="0.0 0.0 0.0" range="-100 -30" type="hinge"/>
            <geom fromto="0.0 0.0 0.0 -0.4099999997764826 -0.4099999997764826 0.0" name="third_ankle_geom" size="0.12935991019010545" type="capsule"/>
          </body>
        </body>
      </body>
      <body name="right_back_leg" pos="0 0 0">
        <geom fromto="0.0 0.0 0.0 0.7 -0.7 0.0" name="aux_4_geom" size="0.08999999977648258" type="capsule"/>
        <body name="aux_4" pos=" 0.7 -0.7 0">
          <joint axis="0 0 1" name="hip_4" pos="0.0 0.0 0.0" range="-40 40" type="hinge"/>
          <geom fromto="0.0 0.0 0.0 0.7 -0.5778027892112731 0.0" name="rightback_leg_geom" size="0.08999999977648258" type="capsule"/>
          <body pos="0.7 -0.5778027892112731 0" >
            <joint axis="1 1 0" name="ankle_4" pos="0.0 0.0 0.0" range="30 100" type="hinge"/>
            <geom fromto="0.0 0.0 0.0 0.4099999997764826 -0.4099999997764826 0.0" name="fourth_ankle_geom" size="0.12935991019010545" type="capsule"/>
          </body>
        </body>
      </body>
    </body>
  </worldbody>

  <actuator>
    <motor ctrllimited="true" ctrlrange="-1.0 1.0" joint="hip_4" gear="150"/>
    <motor ctrllimited="true" ctrlrange="-1.0 1.0" joint="ankle_4" gear="150"/>
    <motor ctrllimited="true" ctrlrange="-1.0 1.0" joint="hip_1" gear="150"/>
    <motor ctrllimited="true" ctrlrange="-1.0 1.0" joint="ankle_1" gear="150"/>
    <motor ctrllimited="true" ctrlrange="-1.0 1.0" joint="hip_2" gear="150"/>
    <motor ctrllimited="true" ctrlrange="-1.0 1.0" joint="ankle_2" gear="150"/>
    <motor ctrllimited="true" ctrlrange="-1.0 1.0" joint="hip_3" gear="150"/>
    <motor ctrllimited="true" ctrlrange="-1.0 1.0" joint="ankle_3" gear="150"/>
  </actuator>
</mujoco>
